2021-03-11 11:36:03,235:ERROR:discord.player: Calling the after function failed.
Traceback (most recent call last):
  File "/home/timorams/PycharmProjects/eeb/venv/lib/python3.8/site-packages/discord/player.py", line 616, in _call_after
    self.after(error)
  File "/home/timorams/PycharmProjects/eeb/cogs/music.py", line 239, in play_next_song
    raise VoiceError(str(error))
cogs.music.VoiceError: [Errno 9] Bad file descriptor
